[
 {
  "author": "pburba", 
  "date": "2009-04-02T13:52:03.282141Z", 
  "msg": [
   "On the subtree-mergeinfo branch: Sync merge from trunk, r36915-36940."
  ], 
  "revision_id": "877015"
 }, 
 {
  "author": "rhuijben", 
  "date": "2009-04-02T13:01:48.805023Z", 
  "msg": [
   "* subversion/libsvn_subr/io.c", 
   "(io_check_path): On Windows, treat a path containing invalid characters as", 
   "a non-existing path. (We already detected invalid drives and invalid", 
   "network paths.) This enables locating the repository root via", 
   "svn_repos_find_root_path() in cases like:", 
   "$ svn mkdir --parents file:///G:/repos/d/f:r/s:t -m \"\""
  ], 
  "revision_id": "877014"
 }, 
 {
  "author": "rhuijben", 
  "date": "2009-04-02T12:57:26.701024Z", 
  "msg": [
   "* subversion/libsvn_subr/dirent_uri.c", 
   "(dirent_previous_segment): On Windows, Only threat a ':' on position 1 of a", 
   "string as segment separator.", 
   "Found as intermediate error when calling:", 
   "$ svn mkdir --parents file:///G:/repos/d/f:r/s:t -m \"\"", 
   "(The real fix is in r36938)."
  ], 
  "revision_id": "877013"
 }, 
 {
  "author": "rhuijben", 
  "date": "2009-04-02T12:54:22.252033Z", 
  "msg": [
   "* subversion/libsvn_delta/path_driver.c", 
   "(svn_delta_path_driver): Split repository path with svn_uri_split().", 
   "Reproducible error on Windows with:", 
   "$ svn mkdir --parents file:///G:/repos/d/f:r/s:t -m \"\"", 
   "(basic_tests.py 36: use folders with names like 'c:hi')"
  ], 
  "revision_id": "877012"
 }, 
 {
  "author": "stylesen", 
  "date": "2009-04-02T10:15:13.836194Z", 
  "msg": [
   "Test issue #3250.", 
   "* subversion/tests/cmdline/merge_tests.py", 
   "(merge_two_edits_to_same_prop): Extend merge test 107, to include test", 
   "for issue #3250."
  ], 
  "revision_id": "877011"
 }
]